2019-12-01 09:13:49,286 ERROR: Exception on /favicon.ico [GET] [in /usr/lib/python3/dist-packages/flask/app.py:1761]
Traceback (most recent call last):
  File "/home/pi/.local/lib/python3.7/site-packages/sqlalchemy/engine/base.py", line 1246, in _execute_context
    cursor, statement, parameters, context
  File "/home/pi/.local/lib/python3.7/site-packages/sqlalchemy/engine/default.py", line 581, in do_execute
    cursor.execute(statement, parameters)
sqlite3.OperationalError: attempt to write a readonly database

The above exception was the direct cause of the following exception:

Traceback (most recent call last):
  File "/usr/lib/python3/dist-packages/flask/app.py", line 2292, in wsgi_app
    response = self.full_dispatch_request()
  File "/usr/lib/python3/dist-packages/flask/app.py", line 1815, in full_dispatch_request
    rv = self.handle_user_exception(e)
  File "/usr/lib/python3/dist-packages/flask/app.py", line 1718, in handle_user_exception
    reraise(exc_type, exc_value, tb)
  File "/usr/lib/python3/dist-packages/flask/_compat.py", line 35, in reraise
    raise value
  File "/usr/lib/python3/dist-packages/flask/app.py", line 1811, in full_dispatch_request
    rv = self.preprocess_request()
  File "/usr/lib/python3/dist-packages/flask/app.py", line 2087, in preprocess_request
    rv = func()
  File "./app/routes.py", line 16, in before_request
    db.session.commit()
  File "/home/pi/.local/lib/python3.7/site-packages/sqlalchemy/orm/scoping.py", line 162, in do
    return getattr(self.registry(), name)(*args, **kwargs)
  File "/home/pi/.local/lib/python3.7/site-packages/sqlalchemy/orm/session.py", line 1027, in commit
    self.transaction.commit()
  File "/home/pi/.local/lib/python3.7/site-packages/sqlalchemy/orm/session.py", line 494, in commit
    self._prepare_impl()
  File "/home/pi/.local/lib/python3.7/site-packages/sqlalchemy/orm/session.py", line 473, in _prepare_impl
    self.session.flush()
  File "/home/pi/.local/lib/python3.7/site-packages/sqlalchemy/orm/session.py", line 2470, in flush
    self._flush(objects)
  File "/home/pi/.local/lib/python3.7/site-packages/sqlalchemy/orm/session.py", line 2608, in _flush
    transaction.rollback(_capture_exception=True)
  File "/home/pi/.local/lib/python3.7/site-packages/sqlalchemy/util/langhelpers.py", line 68, in __exit__
    compat.reraise(exc_type, exc_value, exc_tb)
  File "/home/pi/.local/lib/python3.7/site-packages/sqlalchemy/util/compat.py", line 153, in reraise
    raise value
  File "/home/pi/.local/lib/python3.7/site-packages/sqlalchemy/orm/session.py", line 2568, in _flush
    flush_context.execute()
  File "/home/pi/.local/lib/python3.7/site-packages/sqlalchemy/orm/unitofwork.py", line 422, in execute
    rec.execute(self)
  File "/home/pi/.local/lib/python3.7/site-packages/sqlalchemy/orm/unitofwork.py", line 589, in execute
    uow,
  File "/home/pi/.local/lib/python3.7/site-packages/sqlalchemy/orm/persistence.py", line 236, in save_obj
    update,
  File "/home/pi/.local/lib/python3.7/site-packages/sqlalchemy/orm/persistence.py", line 996, in _emit_update_statements
    statement, multiparams
  File "/home/pi/.local/lib/python3.7/site-packages/sqlalchemy/engine/base.py", line 982, in execute
    return meth(self, multiparams, params)
  File "/home/pi/.local/lib/python3.7/site-packages/sqlalchemy/sql/elements.py", line 287, in _execute_on_connection
    return connection._execute_clauseelement(self, multiparams, params)
  File "/home/pi/.local/lib/python3.7/site-packages/sqlalchemy/engine/base.py", line 1101, in _execute_clauseelement
    distilled_params,
  File "/home/pi/.local/lib/python3.7/site-packages/sqlalchemy/engine/base.py", line 1250, in _execute_context
    e, statement, parameters, cursor, context
  File "/home/pi/.local/lib/python3.7/site-packages/sqlalchemy/engine/base.py", line 1476, in _handle_dbapi_exception
    util.raise_from_cause(sqlalchemy_exception, exc_info)
  File "/home/pi/.local/lib/python3.7/site-packages/sqlalchemy/util/compat.py", line 398, in raise_from_cause
    reraise(type(exception), exception, tb=exc_tb, cause=cause)
  File "/home/pi/.local/lib/python3.7/site-packages/sqlalchemy/util/compat.py", line 152, in reraise
    raise value.with_traceback(tb)
  File "/home/pi/.local/lib/python3.7/site-packages/sqlalchemy/engine/base.py", line 1246, in _execute_context
    cursor, statement, parameters, context
  File "/home/pi/.local/lib/python3.7/site-packages/sqlalchemy/engine/default.py", line 581, in do_execute
    cursor.execute(statement, parameters)
sqlalchemy.exc.OperationalError: (sqlite3.OperationalError) attempt to write a readonly database
[SQL: UPDATE user SET last_seen=? WHERE user.id = ?]
[parameters: ('2019-12-01 17:13:49.281942', 1)]
(Background on this error at: http://sqlalche.me/e/e3q8)
2019-12-01 09:15:58,935 INFO: Microblog startup [in ./app/__init__.py:49]
2019-12-01 09:21:13,665 INFO: Microblog startup [in ./app/__init__.py:49]
2019-12-01 10:50:28,464 INFO: Microblog startup [in ./app/__init__.py:49]
2019-12-01 10:51:18,534 INFO: Microblog startup [in ./app/__init__.py:49]
2019-12-01 10:52:38,533 INFO: Microblog startup [in ./app/__init__.py:49]
2019-12-01 10:54:29,956 INFO: Microblog startup [in ./app/__init__.py:49]
2019-12-01 11:02:34,182 INFO: Microblog startup [in ./app/__init__.py:49]
2019-12-01 11:03:11,980 INFO: Microblog startup [in ./app/__init__.py:49]
2019-12-01 11:41:40,810 INFO: Microblog startup [in ./app/__init__.py:49]
2019-12-01 13:35:46,278 INFO: Microblog startup [in ./app/__init__.py:49]
2019-12-01 13:45:16,534 INFO: Microblog startup [in ./app/__init__.py:49]
2019-12-01 13:50:19,720 INFO: Microblog startup [in ./app/__init__.py:49]
2019-12-01 13:52:17,935 INFO: Microblog startup [in ./app/__init__.py:49]
2019-12-01 14:16:15,817 INFO: Microblog startup [in ./app/__init__.py:49]
2019-12-01 14:18:52,743 INFO: Microblog startup [in ./app/__init__.py:49]
2019-12-01 14:29:40,391 INFO: Microblog startup [in ./app/__init__.py:49]
